2022-02-12 21:48:12,907 INFO: Microblog startup [in E:\git\py_blog2\app\__init__.py:45]
2022-02-12 21:48:31,065 ERROR: Exception on /edit_profile [POST] [in e:\git\py_blog2\venv\lib\site-packages\flask\app.py:1458]
Traceback (most recent call last):
  File "e:\git\py_blog2\venv\lib\site-packages\sqlalchemy\engine\base.py", line 1803, in _execute_context
    cursor, statement, parameters, context
  File "e:\git\py_blog2\venv\lib\site-packages\sqlalchemy\engine\default.py", line 732, in do_execute
    cursor.execute(statement, parameters)
sqlite3.IntegrityError: UNIQUE constraint failed: user.username

The above exception was the direct cause of the following exception:

Traceback (most recent call last):
  File "e:\git\py_blog2\venv\lib\site-packages\flask\app.py", line 2073, in wsgi_app
    response = self.full_dispatch_request()
  File "e:\git\py_blog2\venv\lib\site-packages\flask\app.py", line 1518, in full_dispatch_request
    rv = self.handle_user_exception(e)
  File "e:\git\py_blog2\venv\lib\site-packages\flask\app.py", line 1516, in full_dispatch_request
    rv = self.dispatch_request()
  File "e:\git\py_blog2\venv\lib\site-packages\flask\app.py", line 1502, in dispatch_request
    return self.ensure_sync(self.view_functions[rule.endpoint])(**req.view_args)
  File "e:\git\py_blog2\venv\lib\site-packages\flask_login\utils.py", line 272, in decorated_view
    return func(*args, **kwargs)
  File "E:\git\py_blog2\app\routes.py", line 91, in edit_profile
    db.session.commit()
  File "<string>", line 2, in commit
  File "e:\git\py_blog2\venv\lib\site-packages\sqlalchemy\orm\session.py", line 1431, in commit
    self._transaction.commit(_to_root=self.future)
  File "e:\git\py_blog2\venv\lib\site-packages\sqlalchemy\orm\session.py", line 829, in commit
    self._prepare_impl()
  File "e:\git\py_blog2\venv\lib\site-packages\sqlalchemy\orm\session.py", line 808, in _prepare_impl
    self.session.flush()
  File "e:\git\py_blog2\venv\lib\site-packages\sqlalchemy\orm\session.py", line 3363, in flush
    self._flush(objects)
  File "e:\git\py_blog2\venv\lib\site-packages\sqlalchemy\orm\session.py", line 3503, in _flush
    transaction.rollback(_capture_exception=True)
  File "e:\git\py_blog2\venv\lib\site-packages\sqlalchemy\util\langhelpers.py", line 72, in __exit__
    with_traceback=exc_tb,
  File "e:\git\py_blog2\venv\lib\site-packages\sqlalchemy\util\compat.py", line 207, in raise_
    raise exception
  File "e:\git\py_blog2\venv\lib\site-packages\sqlalchemy\orm\session.py", line 3463, in _flush
    flush_context.execute()
  File "e:\git\py_blog2\venv\lib\site-packages\sqlalchemy\orm\unitofwork.py", line 456, in execute
    rec.execute(self)
  File "e:\git\py_blog2\venv\lib\site-packages\sqlalchemy\orm\unitofwork.py", line 633, in execute
    uow,
  File "e:\git\py_blog2\venv\lib\site-packages\sqlalchemy\orm\persistence.py", line 241, in save_obj
    update,
  File "e:\git\py_blog2\venv\lib\site-packages\sqlalchemy\orm\persistence.py", line 1001, in _emit_update_statements
    statement, multiparams, execution_options=execution_options
  File "e:\git\py_blog2\venv\lib\site-packages\sqlalchemy\engine\base.py", line 1614, in _execute_20
    return meth(self, args_10style, kwargs_10style, execution_options)
  File "e:\git\py_blog2\venv\lib\site-packages\sqlalchemy\sql\elements.py", line 326, in _execute_on_connection
    self, multiparams, params, execution_options
  File "e:\git\py_blog2\venv\lib\site-packages\sqlalchemy\engine\base.py", line 1491, in _execute_clauseelement
    cache_hit=cache_hit,
  File "e:\git\py_blog2\venv\lib\site-packages\sqlalchemy\engine\base.py", line 1846, in _execute_context
    e, statement, parameters, cursor, context
  File "e:\git\py_blog2\venv\lib\site-packages\sqlalchemy\engine\base.py", line 2027, in _handle_dbapi_exception
    sqlalchemy_exception, with_traceback=exc_info[2], from_=e
  File "e:\git\py_blog2\venv\lib\site-packages\sqlalchemy\util\compat.py", line 207, in raise_
    raise exception
  File "e:\git\py_blog2\venv\lib\site-packages\sqlalchemy\engine\base.py", line 1803, in _execute_context
    cursor, statement, parameters, context
  File "e:\git\py_blog2\venv\lib\site-packages\sqlalchemy\engine\default.py", line 732, in do_execute
    cursor.execute(statement, parameters)
sqlalchemy.exc.IntegrityError: (sqlite3.IntegrityError) UNIQUE constraint failed: user.username
[SQL: UPDATE user SET username=?, about_me=? WHERE user.id = ?]
[parameters: ('b', '今天天气不错!!!@', 1)]
(Background on this error at: https://sqlalche.me/e/14/gkpj)
2022-02-12 21:54:19,476 INFO: Microblog startup [in E:\git\py_blog2\app\__init__.py:45]
2022-02-13 20:23:22,065 INFO: Microblog startup [in E:\git\py_blog2\app\__init__.py:45]
2022-02-13 20:23:35,377 INFO: Microblog startup [in E:\git\py_blog2\app\__init__.py:45]
2022-02-13 20:23:45,735 INFO: Microblog startup [in E:\git\py_blog2\app\__init__.py:45]
